Workbook

Sheet Протокол пошуку
A1: № | B1: Дата пошуку | C1: База даних | D1: Пошуковий запит | E1: Кількість результатів | F1: Після фільтрації за роками | G1: Релевантних за назвою і анотацією | H1: Примітки
A2: 1 | B2: =DATE(2026,3,16) -> 46097 | C2: Google Scholar | D2: "course similarity" OR "syllabus similarity" NLP embedding | E2: 118 | F2: 116 | G2: 75 | H2: Відібрано по 10
A3: 2 | B3: =DATE(2026,3,16) -> 46097 | C3: Google Scholar | D3: "curriculum analysis" "natural language processing" semantic | E3: 239 | F3: 206 | G3: 92
A4: 3 | B4: =DATE(2026,3,16) -> 46097 | C4: Google Scholar | D4: "learning outcomes" alignment NLP "text mining" | E4: 2 230 | F4: 2 170 | G4: 104
A5: 4 | B5: =DATE(2026,3,16) -> 46097 | C5: Google Scholar | D5: "semantic search" education course syllabus embedding | E5: 15 700 | F5: 14 600 | G5: 110
A6: 5 | B6: =DATE(2026,3,16) -> 46097 | C6: Google Scholar | D6: allintitle:course similarity | E6: 144 | F6: 89 | G6: 55 | H6: Не було відібрано, бо міститять тіж самі роботи, що вище
A7: 6 | B7: =DATE(2026,3,16) -> 46097 | C7: Google Scholar | D7: allintitle:syllabus analysis | E7: 798 | F7: 478 | G7: 88
A8: 7 | B8: =DATE(2026,3,16) -> 46097 | C8: Google Scholar | D8: allintitle:curriculum NLP | E8: 22 | F8: 20 | G8: 12
A9: 8 | B9: =DATE(2026,3,16) -> 46097 | C9: Google Scholar | D9: intitle:"learning outcomes" intitle:alignment | E9: 139 | F9: 115 | G9: 67
A10: 9 | B10: =DATE(2026,3,16) -> 46097 | C10: Google Scholar | D10: allintitle:course matching | E10: 185 | F10: 103 | G10: 82
A11: 10 | B11: =DATE(2026,3,16) -> 46097 | C11: Google Scholar | D11: allintitle:syllabus comparison | E11: 44 | F11: 27 | G11: 19
A12: 11 | B12: =DATE(2026,3,16) -> 46097 | C12: Google Scholar | D12: allintitle:course equivalency | E12: 42 | F12: 20 | G12: 11
A13: 12 | B13: =DATE(2026,3,16) -> 46097 | C13: Google Scholar | D13: allintitle:syllabus similarity | E13: 6 | F13: 6 | G13: 3
A14: 13 | B14: =DATE(2026,3,16) -> 46097 | C14: Google Scholar | D14: "подібність курсів" OR "порівняння силабусів" OR "порівняння навчальних програм" | E14: 139 | F14: 113 | G14: 2 | H14: Відібрано 2
A15: 14 | B15: =DATE(2026,3,16) -> 46097 | C15: Google Scholar | D15: "аналіз навчальних програм" OR "аналіз робочих програм" embedding | E15: 5 | F15: 5 | G15: 1 | H15: Відібрано 1
A16: 15 | B16: =DATE(2026,3,16) -> 46097 | C16: Google Scholar | D16: "семантичний аналіз" OR "семантичний пошук" "навчальні матеріали" OR "освітній контент" | E16: 197 | F16: 182 | G16: 3 | H16: Відібрано 3
A17: 16 | B17: =DATE(2026,3,16) -> 46097 | C17: Google Scholar | D17: NLP OR "natural language processing" "навчальні програми" OR "силабус" OR "освіта" | E17: 2 000 | F17: 1 920 | G17: 2 | H17: Відібрано 2

Sheet Відібрані роботи
A1: № | B1: Автори | C1: Рік | D1: Назва роботи | E1: DOI / URL | F1: Короткий зміст / Анотація | G1: Примітки
A2: 1 | B2: Yinuo Xu, Zach A. Pardos | C2: 2024 | D2: Extracting Course Similarity Signal using Subword Embeddings | E2: https://dl.acm.org/doi/abs/10.1145/3636555.3636903 | F2: Several studies have shown the utility of neural network models in learning course similarities and providing insightful course recommendations from enrollment data. In this study, we explore if additional signals can be found in the morphological structure of course names. We train skip-gram, FastText, and other combination models on these course sequence data from the past nine years and compare results with state-of-the-art models. We find a 97.95% improvement in model performance (as measured by recall @ 10 in similarity-based course recommendations) from skip-gram to FastText, and 80.75% improvement from the current best combination model to the previous state-of-the-art model, indicating that the naming convention of courses (e.g., PHYS_H101) carries valuable signals. We define attributes with which to categorize course pairs from our validation set and present an analysis of which models are strongest and weakest at predicting the similarity of which categories of course pairs. Additionally, we also explore course-taking culture, analyzing if courses with the same demographic features are learned to be more similar. Our approach could help students find alternatives to full courses, improve existing course recommendation systems and course articulations between institutions, and assist institutions in course policy-making. | G2: ='Протокол пошуку'!$D$2 -> "course similarity" OR "syllabus similarity" NLP embedding
A3: 2 | B3: Olivera Kitanović, Aleksandra Tomašević, Mihailo Škorić, Ranka Stanković, Ljiljana Kolonja | C3: 2024 | D3: Semantic Textual Similarity of Courses Based on Text Embeddings | E3: https://link.springer.com/chapter/10.1007/978-3-031-71419-1_27 | F3: This paper explores the application of textual embeddings to measure semantic similarity between educational courses’ curriculums, aiming to enhance the effectiveness of the next faculty accreditation. Leveraging state-of-the-art natural language processing techniques, we employ pre-trained embeddings to capture the semantic meaning of course descriptions. Our methodology involves transforming course curriculum texts into high-dimensional vector representations, enabling efficient and meaningful comparisons. We evaluate the proposed approach on a diverse dataset of course descriptions, employing established benchmarks for semantic textual similarity . The results demonstrate the effectiveness of our method in capturing nuanced semantic relationships between courses.
A4: 3 | B4: Indu Joseph Thoppil, Arunkumar Gopu, Jayita Saha | C4: 2025 | D4: BERT Based Word Embedding for Course Similarity Analysis and Clustering Evaluation Using Silhouette Score | E4: https://ieeexplore.ieee.org/abstract/document/11306811/authors#authors | F4: In the era of digital education, personalized course recommendations are essential for guiding students toward relevant learning opportunities. However, accurately assessing course similarity remains a significant challenge due to the semantic complexity of course descriptions and the inefficacy of traditional text-matching techniques. Existing approaches often fail to capture deep contextual relationships, leading to suboptimal recommendations. To address this, we leverage Bert framework, an advanced word embedding model, to generate dense vector representations that preserve semantic nuances.To improve interpretability, dimensionality reduction, followed by K-means clustering is applied to organize similar courses. The Silhouette Score assesses cluster cohesion and separation, ensuring optimal grouping. By incorporating advanced word embeddings, similarity computations, and clustering techniques, this study provides a robust framework for refining course recommendations, enabling better decision-making in educational platforms.
A5: 4 | B5: Östensson Emilia | C5: 2025 | D5: Text analysis techniques and determining the similarity of course contents | E5: https://www.diva-portal.org/smash/record.jsf?pid=diva2%3A1937821&dswid=9903 | F5: Natural language processing is an ever-growing subfield of AI that has a multitude of different applications. A common and seemingly straightforward application is document similarity, which often implements various NLP algorithms. However, along with the versatility of its different techniques, there are also drawbacks. The different algorithms tend to focus on one or more factors of similarity, which means they can excel in one type of similarity assessment but struggle with another. This thesis investigates three NLP techniques with a focus on their ability to automate similarity assessments. Their focus is on similarity between course content for use in course eligibility or course crediting. At this point in time, this comparison is done manually. To determine what factors are important when crediting courses, three algorithms have been implemented and run on various course comparison tests. The algorithms and factors chosen were TF-IDF for weighted term overlap, N-Gram for contextual matching, and NER with Keyword extraction for topic detection. When assessing their overall accuracy, NER with Keyword extraction seemed the best choice. That is until it became apparent that it was more consistently and confidently giving wrong answers. It gave a high similarity score on courses that had some similarities, such as being from the same university but were not similar enough to be credited as each other. Using N-Grams to determine similarity was the most reliable both on similar and dissimilar courses and was shown to be the reliable choice. TF-IDF did not perform adequately with its current vocabulary. To summarize, context-based similarity with N-Grams proved to be a reliable and useful factor when looking into automatic crediting of courses but needs further work before actual usage.
A6: 5 | B6: Elfayoumi Doaa | C6: 2026 | D6: Content-Based Course Recommendation | E6: https://hdl.handle.net/10012/22890 | F6: Choosing university courses can be overwhelming for students, especially in large institutions where hundreds of options are offered each term. Motivated by these observations, I envisioned developing a system that could help students identify educational pathways aligned with their goals and aspirations. By leveraging the University of Waterloo’s course and student data, this research aims to design a recommendation system that suggests courses based on students’ interests and desired career outcomes. To address several challenges, including the lack of aggregate historical enrollment data, this thesis presents a new AI-based course recommendation system designed specifically for the University of Waterloo. The system combines a knowledge graph, semantic similarity techniques, and a custom \textit{interestingness} score to recommend courses that are not only eligible but also meaningful and relevant to the student. The knowledge graph models relationships between courses, programs, prerequisites, terms, and subjects, allowing the system to reason about eligibility in a transparent way. To capture course similarity, I compare two embedding models, sBERT and OpenAI embeddings, and evaluate them by examining their similarity matrices and observing how subjects naturally cluster together. Based on these results, sBERT was selected for the final system due to its strong performance and ability to run locally without API costs. The system also integrates a personalized scoring method that considers prerequisite depth, program requirements, and students’ enrollment history, helping surface courses students might not otherwise discover. This thesis also explores how Large Language Models (LLMs), such as ChatGPT, can support recommendation tasks. Recent studies show that LLMs can enhance existing recommenders through feature extraction, prompt-based ranking, explanation generation, and improved handling of cold-start cases. In this project, LLMs are used as a complementary tool, primarily for generating code from text that represents course prerequisites. The resulting system embodies a hybrid AI approach that blends LLM-driven semantic understanding with knowledge-graph-based reasoning to deliver more intelligent, context-aware recommendations. Overall, this work demonstrates a practical and scalable approach to course recommendation. By combining structured academic data with semantic similarity and AI-driven reasoning, this research shows how natural language processing, large language models, and knowledge-graph reasoning can come together to create an adaptable and effective framework for educational recommendation systems.
A7: 6 | B7: Hasib Shaikh, Arun Kumar | C7: 2021 | D7: A Comparison between Syllabus of AICTE and various Universities - An NLP Based Approach | E7: https://ieeexplore.ieee.org/abstract/document/9456391 | F7: This paper focuses on comparative studies between the syllabus of AICTE and various Universities across India and will recommend the changes to be done so as to have holistic development. Today's generation needs to be updated with the technical world. In spite of the growing engineer population, unemployment is on the verge. This is because they have degrees but are not technically skilled. It has become necessary that engineering graduate should possess a set of skills which encompass technical skills and practical knowledge. This paper focuses on NLP based approach and lists the topics which are lagging in those universities as compared to the AICTE syllabus. It also lists the topics which are upfront and updated in those universities and together it provides the means to improve the syllabus.Each course is designed with specific Course Outcomes (COs) and each CO is mapped to the Program Outcome (PO). Hence Course Outcome attainment and mapping of Course Outcome with Program Outcome play a vital role in Outcome-based education (OBE). The attainment of Course Outcomes is quantified by assessing students. Program Outcomes need to be achieved so as to measure the attainment of a particular program. Hence, the program outcomes need to be linked properly. This paper also focuses that if a particular topic is not covered, it will show the Course Outcome not attained for that particular topic. This process will surely help in structuring the syllabus to effectively reach the desired Outcome Based Education goals. A dataset of topics for each module for various courses has been collected and processed through punctuation and stop words, tokenization, stemming, and term weighting.
A8: 7 | B8: Sumathy Krishnan, Surendran R, Ramkumar Valluru, Venkatesh J | C8: 2025 | D8: AI Course Equivalency using Word Mover's Distance and Semantic Analysis with NLP in Cloud Computing | E8: https://ieeexplore.ieee.org/abstract/document/11042139 | F8: International students and job seekers need assessments of credential equivalence between nations and learning institutions to enter educational programs worldwide. Current manual assessment methods, such as educational equivalency, operate at a slow pace and rely on unreliable methods, which limits their potential for widespread adoption. Study results indicate Word Mover's Distance (WMD) developed within Natural Language Processing (NLP) offers the most effective solution for analyzing the meaning of academic qualifications. When use WMD analysis on course descriptions and learning outcomes, it may get better contextual equivalence assessment methods that fix problems with older assessment methods. The recommended system implements WMD technology for automatic equivalence assessment through cloud infrastructure processing. The recommended system integrates cloud computing benefits and computational capabilities to manage large quantities of information and perform thorough semantic evaluations. Multiple course description datasets from different institutions examine the effectiveness of WMD against known similarity measurements such as cosine and Jaccard similarity. According to the study, WMD is better at finding similar courses because it uses contextual connections between different course sections. Using both developed heatmaps and semantic embeddings together makes it easier to see outcome data because they show the same information in ways that are easy to understand. The worldwide business sector benefits from cloud computing, which delivers adaptive system frameworks together with real-time computing operations throughout expandable resources that users at any location can reach. The system creates a full automated way to compare credentials by combining educational outcomes with employee requirements and academic standards around the world. According to research, cloud platforms based on natural language processing can set up objective structured systems that help countries work together on education and the workforce.
A9: 8 | B9: Chandrasekaran Dhivya | C9: 2021 | D9: Exploiting semantic similarity models to automate transfer credit assessment in academic mobility | E9: https://knowledgecommons.lakeheadu.ca/items/90c9fac5-4296-4026-a7c1-aa709fc07179 | F9: Student mobility or academic mobility involves students moving between institutions during their post-secondary education, and one of the challenging tasks in this process is to assess the transfer credits to be offered to the incoming student. In general, this process involves domain experts comparing the learning outcomes (LOs) of the courses, and based on their similarity deciding on offering transfer credits to the incoming students. This manual im- plementation of the task is not only labor-intensive but also influenced by undue bias and administrative complexity. This research work focuses on identifying an algorithm that ex- ploits the advancements in the field of Natural Language Processing (NLP) to effectively automate this process. A survey tracing the evolution of semantic similarity helps under- stand the various methods available to calculate the semantic similarity between text data. The basic units of comparison namely, learning outcomes are made up of two components namely the descriptor part which provides the contents covered, and the action word which provides the competency achieved. Bloom’s taxonomy provides six different levels of com- petency to which the action words fall into. Given the unique structure, domain specificity, and complexity of learning outcomes, a need for designing a tailor-made algorithm arises. The proposed algorithm uses a clustering-inspired methodology based on knowledge-based semantic similarity measures to assess the taxonomic similarity of learning outcomes and a transformer-based semantic similarity model to assess the semantic similarity of the learning outcomes. The cumulative similarity between the learning outcomes is further aggregated to form course to course similarity. Due to the lack of quality benchmark datasets, a new benchmark dataset is built by conducting a survey among domain experts with knowledge in both academia and computer science. The dataset contains 7 course-to-course similarity values annotated by 5 domain experts. Understanding the inherent need for flexibility in the decision-making process the aggregation part of the algorithm offers tunable parame- ters to accommodate different scenarios. Being one of the early research works in the field of automating articulation, this thesis establishes the imminent challenges that need to be addressed in the field namely, the significant decrease in performance by state-of-the-art se- mantic similarity models with an increase in complexity of sentences, lack of large datasets to train/fine-tune existing models, lack of quality in available learning outcomes, and reluc- tance to share learning outcomes publicly. While providing an efficient algorithm to assess the similarity between courses with existing resources, this research work steers future re- search attempts to apply NLP in the field of articulation in an ideal direction by highlighting the persisting research gaps.
A10: 9 | B10: Armaneesa Naaman Hasoon, Salwa Khalid Abdulateef, R. S. Abdulameer, Moceheb Lazam Shuwandy | C10: 2025 | D10: An Intelligent Hybrid AI Course Recommendation Framework Integrating BERT Embeddings and Random Forest Classification | E10: https://www.mdpi.com/2073-431X/14/9/353 | F10: With the proliferation of online learning platforms, selecting appropriate artificial intelligence (AI) courses has become increasingly complex for learners. This study proposes a novel hybrid AI course recommendation framework that integrates Term Frequency–Inverse Document Frequency (TF-IDF) and Bidirectional Encoder Representations from Transformers (BERT) for robust textual feature extraction, enhanced by a Random Forest classifier to improve recommendation precision. A curated dataset of 2238 AI-related courses from Udemy was constructed through multi-session web scraping, followed by comprehensive data preprocessing. The system computes semantic and lexical similarity using cosine similarity and fuzzy matching to handle user input variations. Experimental results demonstrate a high recommendation accuracy = 91.25%, precision = 96.63%, and F1-Score = 90.77%. Compared with baseline models, the proposed framework significantly improves performance in cold-start scenarios and does not rely on historical user interactions. A Flask-based web application was developed for real-time deployment, offering instant, user-friendly recommendations. This work contributes a scalable and metadata-driven AI recommender architecture with practical deployment and promising generalization capabilities.
A11: 10 | B11: Sumathy Krishnan, Surendran R, Poornima Jayaraman, Sathish Kumar P. J | C11: 2025 | D11: Advanced Course Equivalence Certification Using NLP Technology through Word Mover's Distance in Global Academic Credit Transfers | E11: https://ieeexplore.ieee.org/abstract/document/10959360 | F11: As the competition for higher education and professional employment intensifies globally, the proper evaluation and translation of academic credits and qualification systems has taken on a key significance. Most classic techniques for evaluating the contents of equivalence course certificates, such as Jaccard Index or Cosine, are too simplistic and do not reveal differences in educational credentials or course materials that are found at a semantically deeper structure. These techniques are primarily based on the surface-level characteristics of the texts, ignoring their inherent pictures. To overcome these challenges, this paper considers the possibility of using methods of Natural Language Processing (NLP), especially Word Mover's Distance, in the context of higher education and professional qualification, academic credit and course equivalency evaluation. WMD, or Word Mover's Distance, is a more sophisticated method of NLP, which describes the food transport distance problem and searches for the optimal distance between two different documents. The advantages of this methodology lie in comparing the course description and qualifications from a different perspective without losing the true meaning of these words in relation to course equivalence certificate comparison. On the basis of our study, we can state that WMD implements better than other conventional approaches and is an appealing solution for credit system transfer, the degree equivalence process evaluation in higher education, and employment clearance services. In this way, WMD applications for NLP purposes will allow for the sustainable recognition of the international qualifications of professionals and students, thus enhancing their movement across borders.
A12: 11 | B12: H. Rashtian, A. Hashemi, L. Macfadyen | C12: 2020 | D12: HARNESSING NATURAL LANGUAGE PROCESSING TO SUPPORT CURRICULUM ANALYSIS | E12: https://library.iated.org/view/RASHTIAN2020HAR | F12: In this paper we describe an innovative pilot implementation of a natural language processing (NLP) tool to support analysis of curriculum. ‘Curriculum’ refers not only to course content, but also to the processes by which learners achieve learning goals, to educator activity that supports learning, and to the context in which teaching and learning occurs. But how do we know whether our curriculum effectively represents current thinking in our field? How can we identify gaps in curriculum, uncover unhelpful redundancies between courses, or discover which elements of curriculum may be out of date, or missing? In higher education, curriculum analysis and mapping processes are now routinely employed to answer such questions, and evaluate and improve the scope and quality of curricula. A variety of frameworks have been proposed to guide such processes. These typically direct reviewers to read course syllabi closely and manually ‘map’ the ways that course elements contribute to program outcomes. Not only is this slow and laborious work, however, but the quality, accuracy and currency of syllabi may be variable or limited. Syllabi documents typically outline course goals, and summarize themes and learning materials at a high level, offering only a thin overview of curriculum. It has been argued, on the other hand, that the richest source of deep understanding of student learning is the text generated to support teaching and learning, and higher education remains overwhelmingly textually-mediated experience. Moreover, when courses are offered in a fully online format, all elements of the curriculum – content, learning activities, educator activity, context – are predominantly constructed in text. Automated analysis of more extensive course text materials – and even complete course content – might therefore support faster, more nuanced and more systematic analysis of curriculum. To investigate and test this possibility, we have built a proof-of-concept tool called CRAgent to harness the power of natural language processing (NLP) for curriculum analysis. NLP draws on insights from the field of computational linguistics and offers increasingly accurate approaches to analysing human language. NLP algorithms allow rapid automated analysis of large volumes of text. Our CRAgent tool combines the NLP power of IBM Watson (which distills concepts and categories from text) with the sophisticated and rapid search processes provided by Elasticsearch. CRAgent allows users to rapidly search course and program content for themes and concepts, beyond simple word matches, to allow more sophisticated mapping of curriculum with stated course and program goals. In this paper, we report on a pilot analysis of the text content of 17 online courses in our fully online master’s program. We evaluate the potential for CRAgent to support curriculum mapping and review processes, and demonstrate that CRAgent can rapidly identify mismatches between stated course outcomes and actual course content, guiding further focussed review and potential curriculum redesign. We also discuss future work with CRAgent that will enhance additional aspects of curriculum review. | G12: ='Протокол пошуку'!D3 -> "curriculum analysis" "natural language processing" semantic
A13: 12 | B13: Iuri Nasu, Mikhail Sergeevich Drobinin, Mark Stanislavovich Efanov, Viacheslav Vladimirovich Lanin | C13: 2024 | D13: Data-Driven Approach to Curriculum Analysis | E13: https://cyberleninka.ru/article/n/data-driven-approach-to-curriculum-analysis | F13: The choice of an educational program is momentous in young people's lives. Given the shortage of time after exams, applicants usually do not have time to analyze possible educational tracks. Furthermore, it requires a thorough study of learning plans. This research addresses the problem proposing the algorithm to data-driven curriculum analysis based on natural language processing of course names or competences listed in learning plans. Moreover, the intelligent software system architecture is described. The method is tested on the curricula scraped from university websites. In order to store the content a data warehouse has been developed. At this time, there are few studies on this topic. The existing ones are either on the early stages of development or scarce on implementation details. They are briefly discussed in this paper.
A14: 13 | B14: Rick L. Brattin | C14: 2025 | D14: OUTCOME VS. MASTERY: A SEMANTIC ANALYSIS CURRICULAR FRAMING IN GRADUATE DATA PROGRAMS | E14: https://www.proquest.com/openview/c69ee185294b2ad8d1cb9e3bba92033b/1?pq-origsite=gscholar&cbl=2032142 | F14: Graduate programs in data analytics differ not only in content but also in how they frame the purpose of analytics education. This study investigates whether business and non-business programs exhibit distinct curricular framing orientations. It hypothesizes that business programs emphasize outcome-oriented framing, presenting analytics as a tool for decision-making and value delivery, while non-business programs emphasize mastery-oriented framing focused on technical depth and methodological rigor. To evaluate this distinction, the study analyzes 1,972 course descriptions from 109 graduate programs using natural language processing techniques capable of identifying semantic similarities in instructional language. The results reveal significant differences in how programs describe the role of analytics, with statistical and validation analyses supporting the hypothesized framing distinction. These findings position framing orientation as a structural feature of curriculum design and provide practical guidance for educators, curriculum developers, and academic leaders seeking to align analytics programs with institutional goals and workforce expectations.
A15: 14 | B15: Vidya Ramnarine, Nicholas Chamansingh, Patrick Hosein | C15: 2025 | D15: Using Natural Language Processing to Correlate University Curricula with Required Job Skills | E15: https://ieeexplore.ieee.org/abstract/document/11166280 | F15: Aligning academic curricula with industry demands is essential for preparing graduates with relevant job-market skills. This study examines the alignment between our University’s Department of Electrical and Computer Engineering (DECE) curriculum and industry job requirements across five thematic areas: Communication Systems, Computer Systems Engineering, Control Systems, Electronic Systems, and Energy Systems. Using Natural Language Processing (NLP), we extract and analyze key skills from course outlines and job postings. Web scraping with Selenium and BeautifulSoup gathers job descriptions, while SkillNER identifies required competencies. We then used Latent Dirichlet Allocation (LDA) topic modeling to assess thematic alignment. Findings reveal that, while core technical concepts are well-represented, emerging technologies and software tools are not. Alignment varies across thematic areas, hence the need for curriculum updates to better reflect industry expectations.
A16: 15 | B16: Paulina Gacek, Weronika T Adrian | C16: 2025 | D16: Automated Curriculum Analysis Using Large Language Models and Knowledge Graphs | E16: https://journals.sagepub.com/doi/abs/10.1177/17248035251360196 | F16: A well-structured curriculum is fundamental for providing students with a coherent and meaningful educational journey. However, distributed authorship, informal rules for writing syllabi, and the constant need for updates make curriculum development a highly challenging task. This paper introduces a novel framework that automates the analysis of existing curricula by detecting areas of inconsistency. It utilizes a Large Language Model to extract core concepts and prerequisite relationships directly from unstructured text in course syllabi. To ensure correctness and uniqueness, the extracted entities are linked to Wikidata, a collaborative and general-purpose knowledge graph. Subsequently, a curriculum knowledge graph is constructed based on the relationships between courses and educational concepts, laying the foundation for automated symbolic analysis. We demonstrate the effectiveness of our approach through experiments on the curriculum of the ‘Computer Science and Intelligent Systems program offered at AGH University of Krakow. The results are promising, as the tool provides actionable insights on how to improve the curriculum and avoid the most common mistakes.
A17: 16 | B17: Marek Miloszb, Aizhan Nazyrovaa, Assel Mukanovac, Gulmira Bekmanovaa, Dmitrii Kuzinc, Gaukhar Aimicheva | C17: 2024 | D17: Ontological approach for competency-based curriculum analysis | E17: https://www.cell.com/heliyon/fulltext/S2405-8440(24)05077-1 | F17: This article is dedicated to the development of a model for competencies within an educational program and its implementation through the use of semantic technologies. The model proposed by the authors is distinctive in that competencies are organized into a hierarchical data structure with arbitrary levels of nesting. Furthermore, the article presents an original solution for modelling the input requirements for studying a course, which is defined in the form of dependencies between the competencies generated by the course and the competencies of other courses. The outcome of this work is an ontological model of a competency-based curriculum, for which the authors have developed and implemented algorithms for data addition and retrieval, as well as for analyzing the consistency of the curriculum in terms of the input requirements for studying a discipline and the learning outcomes from previous periods. The findings presented in the article will prove to be valuable in the development of educational process management information systems and educational program constructors. They will also be instrumental in aligning diverse educational programs within the context of academic mobility.
A18: 17 | B18: Nabila Ayman, Md Nour Hossain | C18: 2025 | D18: From Text to Structure: Towards an Intelligent Framework for Evaluating Course Syllabus Completeness Leveraging NLP-Based Approach | E18: https://papers.iafor.org/wp-content/uploads/papers/ece2025/ECE2025_95851.pdf | F18: A syllabus is a roadmap for instructors and students to successfully navigate and complete a course. A well-developed intelligent system for checking syllabus coherence and completeness can significantly enhance curriculum design and overall educational quality. Numerous educational research emphasize that a proper syllabus should contain several key components, including instructor contacts, course information, course description, course objectives, course outline or schedule, course requirements, alignment with program outcomes, course evaluation methods, prerequisites, required materials, grading scale, institutional policies, and additional course materials. However, despite the importance of these elements, many syllabi in practice suffer from inconsistencies, incompleteness, or a lack of alignment with institutional and accreditation standards. These shortcomings can diminish the overall quality of education and lead to disengagement among students. Based on our literature review and to the best of our knowledge, there is currently no standardized automated tool available to evaluate whether a specific course syllabus meets these essential criteria. In this study, we propose a Natural Language Processing (NLP) technique that extracts and interprets the textual content of a course syllabus, identifies key components, and compares them against standardized syllabus templates. The system calculates a completeness score for the syllabus and highlights components that are either incomplete or missing. The system is currently in development and has shown initial success in detecting structural components within sample syllabi. The goal is to establish an automated, intelligent tool that benefits educators and academic institutions by supporting optimized curriculum structuring that aligns with educational standards and learning objectives.
A19: 18 | B19: HoSung Woo, JaMee Kim, WonGyu Lee | C19: 2020 | D19: Development of Curriculum Design Support System Based on Word Embedding and Terminology Extraction | E19: https://www.mdpi.com/2079-9292/9/4/608 | F19: The principles of computer skills have been included in primary and secondary educated since the early 2000s, and the reform of curricula is related to the development of IT. Therefore, curricula should reflect the latest technological trends and needs of society. The development of a curriculum involves the subjective judgment of a few experts or professors to extract knowledge from several similar documents. More objective extraction needs to be based on standardized terminology, and professional terminology can help build content frames for organizing curricula. The purpose of this study is to develop a smart system for extracting terms from the body of computer science (CS) knowledge and organizing knowledge areas. The extracted terms are composed of semantically similar knowledge areas, using the word2vec model. We analyzed a higher-education CS standards document and compiled a dictionary of technical terms with a hierarchical clustering structure. Based on the developed terminology dictionary, a specialized system is proposed to enhance the efficiency and objectivity of terminology extraction. The analysis of high school education courses in India and Israel using the technical term extraction system found that (1) technical terms for Software Development Fundamentals were extracted at a high rate in entry-level courses, (2) in advanced courses, the ratio of technical terms in the areas of Architecture and Organization, Programming Languages, and Software Engineering areas was high, and (3) electives that deal with advanced content had a high percentage of technical terms related to information systems.
A20: 19 | B20: Kirsty Kitto, Nikhil Sarathy, Aleksandr Gromov, Ming Liu, Katarzyna Musial, Simon Buckingham Shum | C20: 2020 | D20: Towards skills-based curriculum analytics: can we automate the recognition of prior learning? | E20: https://dl.acm.org/doi/abs/10.1145/3375462.3375526 | F20: In an era that will increasingly depend upon lifelong learning, the LA community will need to facilitate the movement and sharing of data and information across institutional and geographic boundaries. This will help us to recognise prior learning (RPL) and to personalise the learner experience. Here, we explore the utility of skills-based curriculum analytics and how it might facilitate the process of awarding RPL between two institutions. We explore the potential utility of combining natural language processing and skills taxonomies to map between subject descriptions for these two different institutions, presenting two algorithms we have developed to facilitate RPL and evaluating their performance. We draw attention to some of the issues that arise, listing areas that we consider ripe for future work in a surprisingly underexplored area.
A21: 20 | B21: Paulina Gacek, Weronika T. Adrian | C21: 2025 | D21: Automatic Curriculum Cohesion Analysis Based on Knowledge Graphs | E21: https://link.springer.com/chapter/10.1007/978-3-031-89366-7_6 | F21: Creating a well-structured and cohesive curriculum is essential for providing students with a meaningful and organized educational experience. However, the complexity and scale of curricula and the need for regular updates make developing a curriculum for a single major a highly challenging task. In this paper, we aim to construct a comprehensive tool designed to automatically analyze existing curricula and identify areas of incoherence. The presented approach utilizes unsupervised learning techniques and large language models (LLMs) to extract the main concepts covered by courses and their prerequisites directly from course syllabi. The extracted entities are then linked to Wikidata entities, ensuring both their correctness and uniqueness. By constructing a knowledge graph based on the relationships between courses and main educational concepts, the cohesion of the curriculum can be systematically verified. The verification process involves checking if all cohesion logic predicates are satisfied, thereby ensuring that the curriculum is both comprehensive and logically structured. The results demonstrate the efficacy of our approach in identifying inconsistencies within educational curricula, thereby aiding in the development of more cohesive and well-organized educational programs.
A22: 21 | B22: Xieling Chen, Haoran Xie, Xiaohui Tao, Fu Lee Wang, Jie Cao | C22: 2024 | D22: Leveraging text mining and analytic hierarchy process for the automatic evaluation of online courses | E22: https://link.springer.com/article/10.1007/s13042-024-02203-6 | F22: This study introduced a multi-criteria decision-making methodology leveraging text mining and analytic hierarchy process (AHP) for online course quality evaluation based on students’ feedback texts. First, a hierarchical structure of online course evaluation criteria was formulated by integrating topics (sub-criteria) identified through topic modeling and interpreted based on transactional distance and technology acceptance theories. Second, the weights of the criteria in the hierarchical structure were determined based on topic proportions. Third, the AHP was employed to determine the overall relative advantage of online courses and their relative advantage within each criterion based on the hierarchical framework and criterion weights. The proposed approach was implemented on the datasets of 6940 reviews for knowledge-seeking courses in Art, Design, and Humanities (D1) and 44,697 reviews for skill-seeking courses in Computer Science, Engineering, and Programming (D2) from Class Central to determine ranking positions of nine courses from both D1 and D2 as alternatives. Results revealed common concerns among knowledge and skill-seeking course learners, encompassing “assessment”, “content”, “effort”, “usefulness”, “enjoyment”, “faculty”, “interaction”, and “structure”. The article provides valuable insights into the online course evaluation and selection processes for learners in D1 and D2 groups. Notably, both groups prioritize “effort” and “faculty”, while D2 learners value “assessment” and “enjoyment”, and D1 learners value “usefulness” more. This study demonstrates the efficacy of leveraging online learner reviews and topic modeling for automating MOOC evaluation and informing learners’ decision-making processes. | G22: ='Протокол пошуку'!D4 -> "learning outcomes" alignment NLP "text mining"
A23: 22 | B23: Muhammad Uzair, Muhammad Uzair Fahim, Haider Tamsil, Ali Mujtaba Durrani | C23: 2025 | D23: A HYBRID NLP AND CLUSTERING-BASED FRAMEWORK FOR INDUSTRY-ALIGNED ACADEMIC COURSE RECOMMENDATIONS | E23: https://thesesjournal.com/index.php/1/article/view/609 | F23: The increasing mismatch between academic programs and the fast changing industry needs pose a major predicament to institutions of higher learning that want to churn out employment-worthy graduates. In this paper, we suggest a hybrid recommendation system composed of Natural Language Processing (NLP), unsupervised clustering, topic modeling and similarity analysis to support learning by matching course content in the university with up-to-date trends in the job market. TF-IDF vectorization was applied and Dice.com data of more than 25,000 job descriptions was used to perform K-Means clustering for grouping job roles in thematic clusters. Dimensionality reduction and visualization of clusters was carried out using Principal Component Analysis (PCA) and dominant skill-based topics within groups were found using the Latent Dirichlet Allocation (LDA). By cosine similarity, these topics were aligned with the academic course outlines to determine similarity. It was found in the experiments that topics were highly semantically coherent (all with a score of more than 0.5) and the cosine similarity between courses and topics showed extreme scores (more than 0.6). The highest similarity (0.742) occurred between Data Analysis and Data Science. There is a great potential in applying the proposed system to cover the academic and enterprise divide through the implementation of data-driven dynamic course creation to meet the current workforce needs.
A24: 23 | B24: Hyeji Yang, Jamee Kim, Wongyu Lee | C24: 2023 | D24: Analyzing the Alignment between AI Curriculum and AI Textbooks through Text Mining | E24: https://www.mdpi.com/2076-3417/13/18/10011 | F24: The field of artificial intelligence (AI) is permeating education worldwide, reflecting societal changes driven by advancements in computing technology and the data revolution. Herein, we analyze the alignment between core AI educational curricula and textbooks to provide guidance on structuring AI knowledge. Text mining techniques using Python 3.10.3 and frame-based content analysis tailored to the computing field are employed to examine a substantial amount of text data within educational curriculum textbooks. We comprehensively examine the frequency of knowledge incorporated in AI curricula, topic structure, and practical tool utilization. The degree to which keywords are reflected in curriculum textbooks and in the textbook characteristics are determined using Term Frequency (TF) and Term Frequency-Inverse Document Frequency (TF-IDF) analysis, respectively. The topic structure distribution is derived by Latent Dirichlet Allocation (LDA) topic modeling and the trained model is visualized using PyLDAvis. Furthermore, the variation in vertical content range or level is investigated by content analysis, considering the tools used to teach similar AI knowledge. Lastly, the implications for AI curriculum structure are discussed in terms of curriculum composition, knowledge construction, practical application, and curriculum utilization. This study provides practical guidance for structuring curricula that effectively foster AI competency based on a systematic research methodology.
A25: 24 | B25: Melnikov A., Botov D., Klenin J. | C25: 2017 | D25: ON USAGE OF MACHINE LEARNING FOR NATURAL LANGUAGE PROCESSING TASKS AS ILLUSTRATED BY EDUCATIONAL CONTENT MINING | E25: https://journals.ssau.ru/ontology/article/view/5946 | F25: In this paper, we review most popular approaches to a variety of natural language processing (NLP) tasks, primarily those, which involve machine learning: from classics to state-of-the-art technologies. Most modern approaches can be separated into three rough categories: ones based on distributional hypothesis, those extracting information from graph-like structures (such as ontologies) and the ones that look for lexico-syntactic patterns in text documents. We focus mainly on the former of the three. Before the analysis can even begin, one of the important steps in preparation stage of NLP is the task of representing words and documents as numeric vectors. There exists a variety of approaches from the most simplistic Bag-of-Words to sophisticated machine learning methods, such as word embedding. Today, in the task of information retrieval the best quality for both English and Russian languages is achieved by approaches based on word embedding algorithms, trained on carefully picked text corpora in conjunction with deep syntactic and semantic analysis using various deep neural networks. A big variety of different machine learning algorithms is being applied for NLP tasks such as Part-of-Speech-tagging, text summarization, named entity recognition, document classification, topic and relation extraction and natural language question answering. We also review possibilities of applying these approaches and methods to educational content analysis, and propose the novel approach to utilizing NLP and machine learning capabilities in analyzing and synthesizing educational content in a form of a decision support systems.
A26: 25 | B26: Law Sheng Xun, Swapna Gottipati, Venky Shankararaman | C26: 2015 | D26: Text-mining approach for verifying alignment of information systems curriculum with industry skills | E26: https://ieeexplore.ieee.org/abstract/document/7217959 | F26: Managing and developing competencies or skills are vital to professional development of an individual. Many tertiary education institutions are therefore focused on developing curriculum that will help the graduating students acquire skills that are aligned with industry practice. Industry skills frameworks such as Skills Framework for the Information Age (SFIA) define the professionals required for an IT professional. Therefore, mapping the curriculum competencies to the industry skills framework has a dual purpose of aiding the educationists to improve the curriculum, and the students to plan the courses according to their career plan. Existing mapping methods are manual and painstaking processes. In this paper, we present an automated solution based on text analytics techniques to map the curriculum to industry framework and provide a visual based analysis to discover the strengths and weakness of the curriculum. We evaluated our solution model on an undergraduate core curriculum; Bachelor of Science (Information Systems Management) degree program BSc (ISM), offered by the School of Information Systems (SIS), Singapore Management University (SMU) and Skills Framework for the Information Age (SFIA).
A27: 26 | B27: Mohammed Badawy, A. A. Abd El-Aziz, Hesham A. Hefny | C27: 2016 | D27: Analysis of learning objectives for higher education textbooks using text mining | E27: https://ieeexplore.ieee.org/abstract/document/7856469 | F27: This study aimed to analyze the learning objectives of the higher education textbooks, according to verbs of intended learning outcomes which were set by the Quality Management of Institute of Statistical Studies and Research (ISSR), Cairo University, Egypt. This study provides a set of recommendations that will help to choose the best chapters of a textbook which is investigating the largest amount of targeted intended learning outcomes that helps explore the key performance indicators for organizations. A dataset of learning objectives for each chapter and intended learning outcomes has been collected. Each learning objective from chapters and the Intended learning outcomes were processed through the removal of punctuation and stop words, tokenization, stemming and term weighting.
A28: 27 | B28: C. Papadimas, V. Ragazou, I. Karasavvidis, V. Kollias | C28: 2025 | D28: Predicting learning performance using NLP: an exploratory study using two semantic textual similarity methods | E28: https://link.springer.com/article/10.1007/s10115-024-02293-2 | F28: Most learning analytics (LA) systems provide generic feedback, because they primarily draw on performance data based on quiz scores. This study explored the potential of student-generated summaries as an alternative method for predicting learning performance. Two hundred and fifty-four undergraduates first watched a series of six short video lectures and then wrote a short summary for each one. Based on their median performance quiz scores, the participants were divided into two performance groups. Sparse and dense text vectorization methods were used to represent the video lectures and student summaries. Three semantic textual similarity features were computed using cosine similarity and were used as input into seven common machine learning algorithms. The results indicated that the sparse similarity features outperformed dense ones in classifying performance. Also, the best classification accuracy was achieved using the K-Nearest Neighbors and Random Forrest algorithms. Overall, the findings suggest that semantic similarity measures can be used as additional proxy measures of learning, thereby enabling the real-time monitoring and evaluation of student understanding in LA contexts.
A29: 28 | B29: K Thirumoorthy, K Muneeswaran | C29: 2021 | D29: An application of text mining techniques and outcome based education: student recruitment system | E29: https://link.springer.com/article/10.1007/s12652-021-03162-4 | F29: Outcome-based education (OBE) is one of the student-centric teaching and learning methodology. The primary objective of the outcome-based education is measuring the student performance through outcomes. Course outcome (CO) reflects the abilities of what a student can do at the end of a course. Assessment of learning outcome is one of the key aspects of teaching-learning process. The attainment of course outcome will be used to improve the teaching, learning process and to evaluate the student’s performance in that course. In this paper, we propose a new student recruitment system to identify the best students based on their Course Outcome attainment. We apply the text mining concept in this teaching learning process to find the best student list based on the recruiter query. The student recruitment process involved with many parameters like technical skill and analytical skill. The quality of the student’s technical skill can be measured by his/her performance in the CO attainment of a particular course or program. This proposed method utilizes data obtained from student’s marks in end semester exams, test, project and other formal assessments.
A30: 29 | B30: Rafael Ferreira-Mello, Máverick André, Anderson Pinheiro, Evandro Costa, Cristobal Romero | C30: 2019 | D30: Text mining in education | E30: https://wires.onlinelibrary.wiley.com/doi/abs/10.1002/widm.1332 | F30: The explosive growth of online education environments is generating a massive volume of data, specially in text format from forums, chats, social networks, assessments, essays, among others. It produces exciting challenges on how to mine text data in order to find useful knowledge for educational stakeholders. Despite the increasing number of educational applications of text mining published recently, we have not found any paper surveying them. In this line, this work presents a systematic overview of the current status of the Educational Text Mining field. Our final goal is to answer three main research questions: Which are the text mining techniques most used in educational environments? Which are the most used educational resources? And which are the main applications or educational goals? Finally, we outline the conclusions and the more interesting future trends.
A31: 30 | B31: Rajkumar Saini, György Kovács, Mohamadreza Faridghasemnia, Hamam Mokayed, Oluwatosin Adewumi, Pedro Alonso, Sumit Rakesh, Marcus Liwicki | C31: 2021 | D31: Pedagogical Principles in the Online Teaching of Text Mining: A Retrospection | E31: https://aclanthology.org/2021.teachingnlp-1.1/ | F31: The ongoing COVID-19 pandemic has brought online education to the forefront of pedagogical discussions. To make this increased interest sustainable in a post-pandemic era, online courses must be built on strong pedagogical foundations. With a long history of pedagogic research, there are many principles, frameworks, and models available to help teachers in doing so. These models cover different teaching perspectives, such as constructive alignment, feedback, and the learning environment. In this paper, we discuss how we designed and implemented our online Natural Language Processing (NLP) course following constructive alignment and adhering to the pedagogical principles of LTU. By examining our course and analyzing student evaluation forms, we show that we have met our goal and successfully delivered the course. Furthermore, we discuss the additional benefits resulting from the current mode of delivery, including the increased reusability of course content and increased potential for collaboration between universities. Lastly, we also discuss where we can and will further improve the current course design.
A32: 31 | B32: Lukas Pfahler, Katharina Morik | C32: 2020 | D32: Semantic Search in Millions of Equations | E32: https://dl.acm.org/doi/abs/10.1145/3394486.3403056 | F32: Given the increase of publications, search for relevant papers becomes tedious. In particular, search across disciplines or schools of thinking is not supported. This is mainly due to the retrieval with keyword queries: technical terms differ in different sciences or at different times. Relevant articles might better be identified by their mathematical problem descriptions. Just looking at the equations in a paper already gives a hint to whether the paper is relevant. Hence, we propose a new approach for retrieval of mathematical expressions based on machine learning. We design an unsupervised representation learning task that combines embedding learning with self-supervised learning. Using graph convolutional neural networks we embed mathematical expression into low-dimensional vector spaces that allow efficient nearest neighbor queries. To train our models, we collect a huge dataset with over 29 million mathematical expressions from over 900,000 publications published on arXiv.org. The math is converted into an XML format, which we view as graph data. Our empirical evaluations involving a new dataset of manually annotated search queries show the benefits of using embedding models for mathematical retrieval. | G32: ='Протокол пошуку'!D5 -> "semantic search" education course syllabus embedding
A33: 32 | B33: Ling Wang, Tingkai Wang, Tie Hua Zhou, Zehuan Liu | C33: 2026 | D33: Course-Oriented Knowledge Service-Based AI Teaching Assistant System for Higher Education Sustainable Development Demand | E33: https://www.mdpi.com/2071-1050/18/2/807 | F33: With the advancement of artificial intelligence and educational informatization, there is a growing demand for intelligent teaching assistance systems in universities. Focusing on the university “Algorithms” course in the computer science department, this study develops a multi-terminal collaborative knowledge service system, Course-Oriented Knowledge Service–Based AI Teaching Assistant System (CKS-AITAS), which consists of a PC terminal and a mobile terminal, where the PC terminal integrates functions including knowledge graph, semantic retrieval, intelligent question-answering, and knowledge recommendation. While the mobile terminal enables classroom check-in and teaching interaction, thus forming a closed-loop platform for teaching organization, resource acquisition, and knowledge inquiry. For the document retrieval module, paragraph-level semantic modeling of textbook content is conducted using Word2Vec, combined with approximate nearest neighbor indexing, and this module achieves an MRR@10 of 0.641 and an average query time of 0.128 s, balancing accuracy and efficiency; the intelligent question-answering module, based on a self-built course FAQ dataset, is trained via the BERT model to enable question matching and answer retrieval, achieving an accuracy rate of 86.3% and an average response time of 0.31 s. Overall, CKS-AITAS meets the core teaching needs of the course, provides an AI-empowered solution for university teaching, and boasts promising application prospects in facilitating education sustainability.
A34: 33 | B34: Hussein T. Al-Natsheh, Lucie Martinet, Fabrice Muhlenbach, Fabien Rico, Djamel A. Zighed | C34: 2017 | D34: Semantic Search-by-Examples for Scientific Topic Corpus Expansion in Digital Libraries | E34: https://ieeexplore.ieee.org/abstract/document/8215735 | F34: In this article we address the problem of expanding the set of papers that researchers encounter when conducting bibliographic research on their scientific work. Using classical search engines or recommender systems in digital libraries, some interesting and relevant articles could be missed if they do not contain the same search key-phrases that the researcher is aware of. We propose a novel model that is based on a supervised active learning over a semantic features transformation of all articles of a given digital library. Our model, named Semantic Search-by-Examples (SSbE), shows better evaluation results over a similar purpose existing method, More-Like-This query, based on the feedback annotation of two domain experts in our experimented use-case. We also introduce a new semantic relatedness evaluation measure to avoid the need of human feedback annotation after the active learning process. The results also show higher diversity and overlapping with related scientific topics which we think can better foster transdisciplinary research.
